Workbook

Sheet Resumen de exportación
B3: Este documento se exportó de Numbers. Cada tabla se convirtió en una hoja de cálculo de Excel. Los demás objetos de las hojas de Numbers se colocaron en distintas hojas de cálculo. Recuerda que el cálculo de fórmulas puede ser diferente en Excel.
B7: Nombre de hoja de Numbers | C7: Nombre de tabla de Numbers | D7: Nombre de hoja de cálculo de Excel
B9: Insumos
C10: Tabla 1 | D10: Insumos
B11: Cantidades
C12: Tabla 1 | D12: Cantidades
B13: Corte
C14: Tabla 1 | D14: Corte
B15: Presupuesto
C16: Tabla 1 | D16: Presupuesto
B17: Criterios
C18: Tabla 1 | D18: Criterios

Sheet Insumos
A1: PRESUPUESTO DE ACUSTIZACIÓN — INSUMOS
A2: Celdas amarillas = completar. Celdas azules = calculadas. No editar azules. Geometría tomada del modelo 3D (Opción B: 12 paneles + 8 trampas).
A3: Leyenda | B3: insumo | C3: {="cálculo"} -> cálculo | D3: Solo tocar amarillo. Al cargar precios, el Presupuesto se actualiza solo.
A5: 1. MONEDA E IMPUESTOS
A6: ARS por 1 USD (tipo de cambio a usar) | C6: 1530 | D6: referencia — editar
A7: IVA aplicable | C7: 0 | D7: 0 = no discrimina IVA
A8: Validez de la cotización (días) | C8: 15
A10: 2. PANELES BANDA ANCHA (60 × 120 × 50 mm) — paredes y techo
A11: Cantidad de paneles | C11: 12
A12: Ancho (m) | C12: 0.6
A13: Alto (m) | C13: 1.2
A14: Espesor del marco (m) | C14: 0.05
A15: Travesaños extra (riostras) | C15: 1
A16: Área de un panel (m²) | C16: {=C12*C13} -> 0.72
A17: Área total paneles (m²) | C17: {=C11*C16} -> 8.64
A19: 3. TRAMPAS DE ESQUINA (panel a 45° × 100 mm) — 2 por esquina, 4 esquinas
A20: Cantidad de trampas | C20: 8
A21: Pierna sobre cada pared (m) | C21: 0.6
A22: Alto (m) | C22: 1.2
A23: Espesor (m) | C23: 0.1
A24: Cara (hipotenusa, m) | C24: {=C21*SQRT(2)} -> 0.84852814 | D24: √2 × pierna — panel plano a 45°
A25: Área de una trampa (m²) | C25: {=C24*C22} -> 1.0182338
A26: Área total trampas (m²) | C26: {=C20*C25} -> 8.1458701
A27: Marcos de 5 cm por trampa | C27: {=ROUNDUP(C23/C14,0)} -> 2 | D27: 100 mm / 50 mm = 2 marcos apilados
A29: 4. FENÓLICO 18 mm — se corta en tiras de 5 cm (listones del marco)
A30: Ancho plancha (m) | C30: 1.22
A31: Largo plancha (m) | C31: 2.44
A32: Espesor placa (m) | C32: 0.018
A33: Precio por plancha (ARS) | C33: 28000
A34: Ancho de tira (m) | C34: 0.05
A35: Kerf / ancho de corte (m) | C35: 0.003
A36: Desperdicio madera | C36: 0.1
A37: Tiras de 5 cm por plancha | C37: {=INT((C30+C35)/(C34+C35))} -> 23 | D37: INT((ancho + kerf) / (tira + kerf))
A38: Metros lineales por plancha | C38: {=C37*C31} -> 56.12
A39: Área de una plancha (m²) | C39: {=C30*C31} -> 2.9768
A41: 5. LANA DE ROCA — Acuflex 100 kg/m³ 50 mm 1200×600
A42: Ancho placa (m) | C42: 0.6
A43: Alto placa (m) | C43: 1.2
A44: Densidad (kg/m³) | C44: 100
A45: Área de una placa (m²) | C45: {=C42*C43} -> 0.72 | D45: 0,72 m² — la cotización viene por m², no por placa
...

Sheet Cantidades
A1: CANTIDADES DERIVADAS DE LA GEOMETRÍA
A2: Todo se recalcula desde Insumos. Esta hoja es el despiece para comprar.
A4: A. MADERA — metros lineales de tira de 5 cm
A5: Pieza | B5: Cant. | C5: Largueros (m) | D5: Travesaños (m) | E5: ml / unidad | F5: ml total | G5: Notas
A6: Panel banda ancha | B6: {='Insumos'!$C$11} -> 12 | C6: {=2*'Insumos'!$C$13} -> 2.4 | D6: {=(2+'Insumos'!$C$15)*('Insumos'!$C$12-2*'Insumos'!$C$32)} -> 1.692 | E6: {=C6+D6} -> 4.092 | F6: {=B6*E6} -> 49.104 | G6: 2 largueros a 1,20 m + cabezales y riostra a (0,60 − 2×18 mm)
A7: Trampa de esquina (todos los marcos) | B7: {='Insumos'!$C$20} -> 8 | C7: {=2*'Insumos'!$C$22*'Insumos'!$C$27} -> 4.8 | D7: {=2*('Insumos'!$C$24-2*'Insumos'!$C$32)*'Insumos'!$C$27} -> 3.2501125 | E7: {=C7+D7} -> 8.0501125 | F7: {=B7*E7} -> 64.4009 | G7: 2 marcos apilados de 5 cm = 10 cm de profundidad
A8: Subtotal marcos | F8: {=F6+F7} -> 113.5049
A10: Desperdicio madera | C10: {='Insumos'!$C$36} -> 0.1
A11: ml a comprar (con desperdicio) | C11: {=F8*(1+'Insumos'!$C$36)} -> 124.85539
A12: ml disponibles por plancha | C12: {='Insumos'!$C$38} -> 56.12
A13: Planchas de fenólico necesarias | C13: {=ROUNDUP(C11/C12,0)} -> 3
A14: Sobrante estimado (ml) | C14: {=C13*C12-C11} -> 43.50461
A15: Costo fenólico (ARS) | C15: {=C13*'Insumos'!$C$33} -> 84000
A17: B. LANA DE ROCA — Acuflex 100 kg/m³ 50 mm, cobrada por m²
A18: Uso | B18: Piezas | C18: Capas | D18: m² neto | E18: m² c/ desp. | F18: Placas | G18: Notas
A19: Paneles 50 mm | B19: {='Insumos'!$C$11} -> 12 | C19: {='Insumos'!$C$51} -> 1 | D19: {='Insumos'!$C$11*'Insumos'!$C$12*'Insumos'!$C$13*'Insumos'!$C$51} -> 8.64 | E19: {=D19} -> 8.64 | F19: {=ROUNDUP(E19/'Insumos'!$C$45,0)} -> 12 | G19: 1 placa por panel (calza 60×120). Sin desperdicio extra.
A20: Trampas 100 mm (2×50 mm) | B20: {='Insumos'!$C$20} -> 8 | C20: {='Insumos'!$C$52} -> 2 | D20: {='Insumos'!$C$20*'Insumos'!$C$24*'Insumos'!$C$22*'Insumos'!$C$52} -> 16.29174 | E20: {=D20*(1+'Insumos'!$C$53)} -> 17.595079 | F20: {=ROUNDUP(E20/'Insumos'!$C$45,0)} -> 25 | G20: Cara 85 cm: se corta placa 60 cm + faja de 25 cm de otra placa
A21: Total lana | D21: {=D19+D20} -> 24.93174 | E21: {=E19+E20} -> 26.235079 | F21: {=F19+F20} -> 37
A22: Costo lana (ARS) | C22: {=F21*'Insumos'!$C$45*'Insumos'!$C$48*'Insumos'!$C$6} -> 825373.8 | D22: 0
A24: C. GABARDINA — m² de tela y metros de rollo de 1,50 m
A25: Pieza | B25: Cant. | C25: Ancho corte (m) | D25: Largo corte (m) | E25: m² / u | F25: m² total | G25: ml rollo
A26: Panel | B26: {='Insumos'!$C$11} -> 12 | C26: {='Insumos'!$C$12+2*'Insumos'!$C$14+2*'Insumos'!$C$57} -> 0.8 | D26: {='Insumos'!$C$13+2*'Insumos'!$C$14+2*'Insumos'!$C$57} -> 1.4 | E26: {=C26*D26} -> 1.12 | F26: {=B26*E26} -> 13.44 | G26: {=B26*D26} -> 16.8
A27: Trampa | B27: {='Insumos'!$C$20} -> 8 | C27: {='Insumos'!$C$24+2*'Insumos'!$C$23+2*'Insumos'!$C$57} -> 1.1485281 | D27: {='Insumos'!$C$22+2*'Insumos'!$C$23+2*'Insumos'!$C$57} -> 1.5 | E27: {=C27*D27} -> 1.7227922 | F27: {=B27*E27} -> 13.782338 | G27: {=B27*D27} -> 12
A28: Subtotal tela | F28: {=F26+F27} -> 27.222338 | G28: {=G26+G27} -> 28.8
A30: m² a comprar (c/ desperdicio) | C30: {=F28*(1+'Insumos'!$C$59)} -> 29.944571
A31: Metros lineales de rollo (conservador) | C31: {=G28*(1+'Insumos'!$C$59)} -> 31.68 | D31: Una pieza detrás de otra. No anida dos paneles en el ancho (0,80+0,80 > 1,50).
A32: Equivalente m² del rollo | C32: {=C31*'Insumos'!$C$56} -> 47.52
A33: Costo gabardina (ARS) | C33: {=C31*'Insumos'!$C$58} -> 348480 | D33: {=IF('Insumos'!$C$58=0,"⚠ falta precio del metro de tela","ok")} -> ok
A35: D. RESUMEN DE COMPRA
A36: Ítem | B36: Unidad | C36: Cantidad | D36: Precio unit. ARS | E36: Subtotal ARS
A37: Fenólico 18 mm | B37: plancha 1,22×2,44 | C37: {=C13} -> 3 | D37: {='Insumos'!$C$33} -> 28000 | E37: {=C15} -> 84000
A38: Acuflex 100 kg/m³ 50 mm | B38: placa 0,60×1,20 | C38: {=F21} -> 37 | D38: {='Insumos'!$C$50} -> 22307.4 | E38: {=C22} -> 825373.8 | F38: 0
A39: Gabardina | B39: m lineal rollo 1,50 | C39: {=C31} -> 31.68 | D39: {='Insumos'!$C$58} -> 11000 | E39: {=C33} -> 348480
A40: Grapas | B40: global | C40: 1 | D40: {='Insumos'!$C$62} -> 20000 | E40: {='Insumos'!$C$62} -> 20000
A41: Cola / adhesivo | B41: global | C41: 1 | D41: {='Insumos'!$C$63} -> 0 | E41: {='Insumos'!$C$63} -> 0
A42: Tornillos / clavos / tarugos | B42: global | C42: 1 | D42: {='Insumos'!$C$64} -> 15000 | E42: {='Insumos'!$C$64} -> 15000
A43: Herrajes de colgado | B43: global | C43: 1 | D43: {='Insumos'!$C$65} -> 0 | E43: {='Insumos'!$C$65} -> 0
A44: Otros / flete | B44: global | C44: 1 | D44: {='Insumos'!$C$66} -> 0 | E44: {='Insumos'!$C$66} -> 0
A45: TOTAL MATERIALES | E45: {=E37+E38+E39+E40+E41+E42+E43+E44} -> 1292853.8

Sheet Corte
A1: PLAN DE CORTE — FENÓLICO 18 mm EN TIRAS DE 5 cm
A2: Cortar las planchas a lo largo (tiras de 2,44 m × 5 cm). Después se tronzan a 1,20 m (largueros) o a 0,564 m (travesaños).
A4: Piezas a obtener
A5: Pieza | B5: Largo (m) | C5: Cantidad | D5: De tira 2,44 m salen | E5: Tiras de 2,44 m | F5: Notas
A6: Larguero de panel | B6: {='Insumos'!$C$13} -> 1.2 | C6: {='Insumos'!$C$11*2} -> 24 | D6: {=INT('Insumos'!$C$31/B6)} -> 2 | E6: {=ROUNDUP(C6/D6,0)} -> 12 | F6: 2 × 1,20 m por tira de 2,44 (sobran 4 cm)
A7: Travesaño / riostra de panel | B7: {='Insumos'!$C$12-2*'Insumos'!$C$32} -> 0.564 | C7: {='Insumos'!$C$11*(2+'Insumos'!$C$15)} -> 36 | D7: {=INT('Insumos'!$C$31/B7)} -> 4 | E7: {=ROUNDUP(C7/D7,0)} -> 9 | F7: 4 piezas de ~0,56 m por tira
A8: Larguero de trampa | B8: {='Insumos'!$C$22} -> 1.2 | C8: {='Insumos'!$C$20*2*'Insumos'!$C$27} -> 32 | D8: {=INT('Insumos'!$C$31/B8)} -> 2 | E8: {=ROUNDUP(C8/D8,0)} -> 16 | F8: 2 marcos × 2 largueros × 8 trampas
A9: Travesaño de trampa | B9: {='Insumos'!$C$24-2*'Insumos'!$C$32} -> 0.81252814 | C9: {='Insumos'!$C$20*2*'Insumos'!$C$27} -> 32 | D9: {=INT('Insumos'!$C$31/B9)} -> 3 | E9: {=ROUNDUP(C9/D9,0)} -> 11 | F9: Cara 85 cm − 36 mm de encuentro
A10: Total tiras de 2,44 m | E10: {=E6+E7+E8+E9} -> 48
A12: Tiras que salen de 1 plancha | C12: {='Insumos'!$C$37} -> 23
A13: Planchas según este anidado | C13: {=ROUNDUP(E10/C12,0)} -> 3
A14: Planchas según ml + 10% (hoja Cantidades) | C14: {='Cantidades'!$C$13} -> 3
A15: Comprar (el mayor de los dos) | C15: {=MAX(C13,C14)} -> 3
A17: Secuencia de corte recomendada
A18: 1. Marcar cada plancha cada 53 mm (50 mm de tira + 3 mm de disco) a lo ancho. 2. Cortar todas las tiras de 2,44 m × 50 mm × 18 mm. Guardar el canto de fábrica como cara vista si queda prolijo. 3. Tronzar primero los largueros de 1,20 m (rinden 2 por tira). Etiquetar P (panel) y T (trampa). 4. Con las tiras restantes, tronzar travesaños de panel (~564 mm) y de trampa (~813 mm). 5. Armar marco a tope: largueros enteros afuera, travesaños entre ellos. Cola + 2 tornillos por encuentro. 6. Trampas: atornillar los dos marcos uno sobre otro (queda caja de 100 mm). Lana en dos capas. 7. Lijar cantos, tapizar con gabardina grapada al dorso, 5 cm de solape.

Sheet Presupuesto
A1: PRESUPUESTO DE ACUSTIZACIÓN
A2: Home studio — habitación PH 3,20 × 3,00 m · tratamiento según modelo 3D (12 paneles + 8 trampas de esquina)
A4: Fecha | B4: {=TODAY()} -> 46265 | C4: Validez (días) | D4: {='Insumos'!$C$8} -> 15 | E4: TC ARS/USD | F4: {='Insumos'!$C$6} -> 1530
A5: Cliente | B5: PH — a completar | E5: IVA | F5: {='Insumos'!$C$7} -> 0
A7: DETALLE
A8: # | B8: Descripción | C8: Cant. | D8: Unidad | E8: P. unitario ARS | F8: Subtotal ARS
A9: FASE 1 — Diagnóstico acústico (define si se avanza con el tratamiento)
A10: 1 | B10: Medición REW — visita preliminar | C10: {='Insumos'!$C$71/'Insumos'!$C$73} -> 2 | D10: h | E10: {='Insumos'!$C$72*'Insumos'!$C$6} -> 45900 | F10: {=('Insumos'!$C$71/'Insumos'!$C$73)*'Insumos'!$C$72*'Insumos'!$C$6} -> 91800
A11: 2 | B11: Medición REW — visita de verificación (post) | C11: {='Insumos'!$C$71/'Insumos'!$C$73} -> 2 | D11: h | E11: {='Insumos'!$C$72*'Insumos'!$C$6} -> 45900 | F11: {=('Insumos'!$C$71/'Insumos'!$C$73)*'Insumos'!$C$72*'Insumos'!$C$6} -> 91800
A12: 3 | B12: Viáticos / traslado | C12: {=IF('Insumos'!$C$74>0,1,0)} -> 1 | D12: global | E12: {='Insumos'!$C$74} -> 200000 | F12: {='Insumos'!$C$74} -> 200000
A13: Subtotal Fase 1 | F13: {=F10+F11+F12} -> 383600
A15: FASE 2 — Construcción de paneles (cantidades según modelo 3D; se confirman con la medición)
A16: 4 | B16: Fenólico 18 mm — plancha 1,22 × 2,44 m (tiras de 5 cm) | C16: {='Cantidades'!$C$13} -> 3 | D16: plancha | E16: {='Insumos'!$C$33} -> 28000 | F16: {='Cantidades'!$C$13*'Insumos'!$C$33} -> 84000
A17: 5 | B17: Acuflex lana mineral 100 kg/m³ 50 mm — 22,50 USD/m² − 10% | C17: {='Cantidades'!$F$21} -> 37 | D17: placa 0,60×1,20 | E17: {='Insumos'!$C$50} -> 22307.4 | F17: {='Cantidades'!$F$21*'Insumos'!$C$50} -> 825373.8
A18: 6 | B18: Gabardina — rollo 1,50 m de ancho | C18: {='Cantidades'!$C$31} -> 31.68 | D18: m lineal | E18: {='Insumos'!$C$58} -> 11000 | F18: {='Cantidades'!$C$31*'Insumos'!$C$58} -> 348480
A19: 7 | B19: Consumibles (grapas, cola, tornillos, herrajes, flete) | C19: {=1} -> 1 | D19: global | E19: {='Insumos'!$C$62+'Insumos'!$C$63+'Insumos'!$C$64+'Insumos'!$C$65+'Insumos'!$C$66} -> 35000 | F19: {='Insumos'!$C$62+'Insumos'!$C$63+'Insumos'!$C$64+'Insumos'!$C$65+'Insumos'!$C$66} -> 35000
A20: Subtotal materiales | F20: {='Cantidades'!$E$45} -> 1292853.8
A21: 8 | B21: Mano de obra de armado (sobre materiales) | C21: {='Insumos'!C70+'Insumos'!C70} -> 1 | D21: % mat. | E21: {='Insumos'!$C$70} -> 0.5 | F21: {='Cantidades'!$E$45*'Insumos'!$C$70} -> 646426.9
A22: 9 | B22: Instalación en obra (colgado) | C22: 1 | D22: global | E22: 180000 | F22: {='Insumos'!$C$67} -> 180000
A23: Subtotal Fase 2 | F23: {=F20+F21+F22} -> 2119280.7
A25: TOTALES
A26: Subtotal neto | F26: {=F13+F23} -> 2502880.7
A27: IVA | F27: {=F26*'Insumos'!$C$7} -> 0
A28: TOTAL | F28: {=F26+F27} -> 2502880.7
A29: Equivalente USD | F29: {=IF('Insumos'!$C$6=0,0,F28/'Insumos'!$C$6)} -> 1635.8697
A31: Condiciones. 1) Las cantidades de la Fase 2 se confirman con la medición de la Fase 1: si el cliente no está en rango, no se compran materiales. 2) Precios de lana y gabardina sujetos a cotización del proveedor (celdas en 0 = pendiente). 3) No incluye micrófono de medición ni corrección de obra (humedad, cielorraso, electricidad). 4) La medición no garantiza un resultado acústico: informa el estado y orienta el tratamiento. 5) Validez según Insumos, por variación de tipo de cambio y de materiales.
A35: Firma / aceptación | D35: Aclaración
A36: ________________________________ | D36: ________________________________

Sheet Criterios
A1: CRITERIOS DE HONORARIOS — NO VA AL CLIENTE
A2: Uso interno. Sirve para decidir si vale la pena ir a medir, y si 30 USD/h y 35% de MO cierran.
A4: 1. Medición: 30 USD/h × 2 h en 2 jornadas
A5: La tarifa de 30 USD/h es razonable (ni cara ni regalada) para un freelance en Argentina que lleva micrófono calibrado, interface y REW, e interpreta la curva. No es tarifa de estudio de ingeniería. Lo que está bajo es el paquete: 2 horas en total repartidas en dos visitas. Cada salida tiene traslado, setup (trípode, calibración, posición de monitores), 20–30 min de medición real y desarme. Facturar 1 h por jornada no cubre el viaje. Recomendación para el presupuesto formal: o bien 30 USD/h con mínimo 2 h por jornada (4 h → 120 USD), o un paquete de 60–80 USD por visita (120–160 USD el pre+post). Si querés usar la medición como filtro barato para ver si el cliente está en rango, cobrá bien la primera visita (60–80 USD) y dejá la segunda incluida en el tratamiento si se confirma.
A10: Escenario | B10: Horas cobradas | C10: USD/h | D10: Total USD | E10: Total ARS | F10: Juicio
A11: Tu cifra (2 h × 2 jornadas) | B11: {='Insumos'!$C$71} -> 4 | C11: {='Insumos'!$C$72} -> 30 | D11: {=B11*C11} -> 120 | E11: {=D11*'Insumos'!$C$6} -> 183600 | F11: Bajo como paquete
A12: Mínimo sano (2 h por jornada) | B12: 4 | C12: {='Insumos'!$C$72} -> 30 | D12: {=B12*C12} -> 120 | E12: {=D12*'Insumos'!$C$6} -> 183600 | F12: Piso
A13: Paquete por visita (70 USD × 2) | B13: 2 | C13: 70 | D13: {=B13*C13} -> 140 | E13: {=D13*'Insumos'!$C$6} -> 214200 | F13: Recomendado
A15: 2. Mano de obra: 35% sobre materiales
A16: 35% sobre materiales es poco para paneles tapizados. El trabajo no es 'armar un marco': es cortar fenólico, 28 marcos (las trampas llevan dos), cargar lana con barbijo, tapizar a grapa y herrajar. Estimación de taller: ~20 h. En ebanistería/tapicería la MO suele ir del 50 al 80% de los materiales; los talleres que venden tratamiento acústico armado suelen multiplicar materiales × 1,5 a 2,0. 35% cierra solo si (a) los materiales son caros y (b) no incluye instalación. Mirá la USD/h implícita de la tabla: si da menos de ~12–15 USD/h de taller, estás subsidiando el trabajo. Piso sano: 50% sin instalación. Con colgado en obra: 70%. Alternativa más limpia: cobrar las horas de taller × una tarifa (p. ej. 15–20 USD/h) y olvidarse del porcentaje.
A21: % MO | B21: MO (ARS) | C21: MO (USD) | D21: USD/h de taller | E21: vs. tus 20 h | F21: Juicio
A22: 35% (tu cifra) | B22: {='Cantidades'!$E$45*0.35} -> 452498.83 | C22: {=IF('Insumos'!$C$6=0,0,B22/'Insumos'!$C$6)} -> 295.75087 | D22: {=IF('Insumos'!$C$75=0,0,C22/'Insumos'!$C$75)} -> 14.787543 | E22: {=IF(D22=0,"cargar precios","")} | F22: Poco
A23: 50% (piso) | B23: {='Cantidades'!$E$45*0.5} -> 646426.9 | C23: {=IF('Insumos'!$C$6=0,0,B23/'Insumos'!$C$6)} -> 422.50124 | D23: {=IF('Insumos'!$C$75=0,0,C23/'Insumos'!$C$75)} -> 21.125062 | F23: Mínimo sin instalación
A24: 70% (con instalación) | B24: {='Cantidades'!$E$45*0.7} -> 904997.66 | C24: {=IF('Insumos'!$C$6=0,0,B24/'Insumos'!$C$6)} -> 591.50174 | D24: {=IF('Insumos'!$C$75=0,0,C24/'Insumos'!$C$75)} -> 29.575087 | F24: Sano si incluye colgado
A25: Tu % actual (Insumos) | B25: {='Cantidades'!$E$45*'Insumos'!$C$70} -> 646426.9 | C25: {=IF('Insumos'!$C$6=0,0,B25/'Insumos'!$C$6)} -> 422.50124 | D25: {=IF('Insumos'!$C$75=0,0,C25/'Insumos'!$C$75)} -> 21.125062 | F25: {=IF('Insumos'!$C$70<0.45,"bajo",IF('Insumos'!$C$70<0.65,"justo","holgado"))} -> justo
A27: Materiales actuales (ARS) | C27: {='Cantidades'!$E$45} -> 1292853.8 | D27: {=IF('Insumos'!$C$58=0,"Falta gabardina: el total de materiales está incompleto.","")}
A29: 3. ¿Vale la pena ir a medir? — filtro de rango
A30: La Fase 1 es el filtro. No compres fenólico ni lana hasta que el cliente acepte un rango, no un número exacto. Cómo pasarle el presupuesto ahora, con lana y gabardina en 0: • Cobrá / acordá la medición preliminar (recomendado: 60–80 USD la primera visita). • Mostrale el despiece: 3 planchas de fenólico, ~37 placas de lana, ~32 m de gabardina, 20 piezas. • Dale un rango de tratamiento, no un total cerrado: 'materiales + 50–70% de armado, se cierra con tus precios'. • Si el cliente se asusta con 3 planchas + 37 placas de lana para una pieza de 9,6 m², no está en rango: no hace falta medir. Si pregunta por etapas (solo trampas, o solo primeras reflexiones), sí está en rango. Orden de trabajo si acepta: medición 1 → ajuste de cantidades → compra → armado → instalación → medición 2.
A35: Señal del cliente | B35: Interpretación
A36: Pide descuento sobre 35% o sobre las 2 h | B36: No está en rango de trabajo pago. Medición solo si la cobrás 100% adelante.
A37: Acepta Fase 1 y pide rango de Fase 2 | B37: Sí: ir a medir. Cerrar cantidades después de la curva.
A38: Quiere 70% de cobertura (Opción A, ~34 paneles) | B38: Subir n_paneles a 34 en Insumos. Recalcula todo. Advertir sala muerta en medios/agudos.
